Workbook

Sheet F1_Test_Cases
A1: STT | B1: Test ID | C1: User Story | D1: Nhóm kiểm thử | E1: Priority | F1: Data mode | G1: Trường hợp | H1: Tình huống thực tế | I1: Tiền điều kiện / Input | J1: Nội dung thực hiện | K1: Kết quả mong đợi | L1: Ground truth / Oracle | M1: Ghi chú | N1: Automated test | O1: Test file | P1: Test level | Q1: Automation status | R1: Gap / Failure reason | S1: Last verified
A2: 1 | B2: F1-TC-001 | C2: F1-US1 | D2: Input & Places | E2: P0 | F2: LIVE | G2: Lập kế hoạch với địa chỉ phổ biến | H2: Chủ xe chuẩn bị đi Hà Nội → Vinh và biết SOC hiện tại. | I2: Origin: Hà Nội; Destination: Vinh; SOC: 60%. | J2: 1. Gõ điểm đi và chọn đúng suggestion Goong. 2. Gõ điểm đến và chọn đúng suggestion. 3. Nhập SOC 60%. 4. Bấm lập kế hoạch. | K2: Trip được chấp nhận; tọa độ được resolve từ Place Detail; planner được gọi; không tự sửa địa điểm người dùng đã chọn. | L2: LIVE: kiểm tra invariants và Place ID/toạ độ được trả từ Goong tại thời điểm test; không cố định số route/trạm. | M2: Case smoke chính. | Q2: NOT_AUTOMATED | R2: Chưa có automated test ánh xạ trực tiếp cho toàn bộ oracle của case này. | S2: 46249
A3: 2 | B3: F1-TC-002 | C3: F1-US1 | D3: Input & Places | E3: P0 | F3: LIVE | G3: Dùng vị trí hiện tại làm điểm xuất phát | H3: Người dùng đang đứng ở Hà Nội và muốn lấy GPS điện thoại thay vì nhập địa chỉ. | I3: Browser đã cấp quyền Location; destination hợp lệ; SOC 70%. | J3: 1. Bấm nút lấy vị trí hiện tại. 2. Chờ GPS resolve. 3. Chọn destination. 4. Lập plan. | K3: Origin được gắn từ GPS/browser; UI hiển thị đúng vị trí; không lấy một địa điểm ngẫu nhiên từ autocomplete. | L3: LIVE: so vị trí với GPS thiết bị trong sai số chấp nhận của browser; không hard-code tọa độ. | M3: GPS F1 chỉ phục vụ chọn origin, không phải telemetry F3. | Q3: NOT_AUTOMATED | R3: Chưa có automated test ánh xạ trực tiếp cho toàn bộ oracle của case này. | S3: 46249
A4: 3 | B4: F1-TC-003 | C4: F1-US1 | D4: Input & Places | E4: P1 | F4: LIVE | G4: Đổi chiều điểm đi và điểm đến | H4: Người dùng nhập nhầm chiều Hà Nội ↔ Vinh rồi bấm nút đảo chiều. | I4: Hai điểm đã được chọn từ suggestion; SOC 80%. | J4: 1. Chọn Hà Nội làm origin, Vinh làm destination. 2. Bấm đổi chiều. 3. Lập plan. | K4: Origin/destination đổi đúng cả label và tọa độ; route được tính theo chiều mới. | L4: LIVE: kiểm tra request gửi backend chứa tọa độ sau khi đảo chiều. | Q4: NOT_AUTOMATED | R4: Chưa có automated test ánh xạ trực tiếp cho toàn bộ oracle của case này. | S4: 46249
A5: 4 | B5: F1-TC-004 | C5: F1-US1 | D5: Input & Places | E5: P1 | F5: LIVE | G5: Tìm địa điểm bằng chuỗi không dấu / sai chính tả nhẹ | H5: Người dùng gõ 'vinh university', 'vinuni', hoặc tên địa điểm không dấu. | I5: Goong Places hoạt động. | J5: 1. Nhập chuỗi gần đúng. 2. Quan sát suggestion. 3. Chọn một kết quả cụ thể. 4. Lập plan. | K5: Hệ thống chỉ dùng địa điểm mà người dùng đã chọn; không tự đoán từ text chưa xác nhận. | L5: LIVE: suggestion phụ thuộc Goong; oracle là selected Place Detail phải khớp request planner. | Q5: NOT_AUTOMATED | R5: Chưa có automated test ánh xạ trực tiếp cho toàn bộ oracle của case này. | S5: 46249
A6: 5 | B6: F1-TC-005 | C6: F1-US1 | D6: Input & Places | E6: P0 | F6: FIXTURE | G6: Địa điểm mơ hồ | H6: Người dùng nhập tên đường/phường có nhiều địa điểm cùng tên. | I6: Fixture Goong trả ≥2 candidate hợp lệ. | J6: 1. Nhập địa chỉ mơ hồ. 2. Không chọn ngay một candidate. 3. Yêu cầu lập plan. | K6: Hệ thống yêu cầu người dùng chọn địa điểm cụ thể; không tự chọn candidate và không chạy planner với tọa độ đoán. | L6: Fixture cố định: expected = AMBIGUOUS/REQUIRES_SELECTION; provider/planner call count sau validation = 0. | N6: test_create_trip_returns_ambiguous_location | O6: tests/test_api/test_trips.py | P6: API | Q6: PASS | R6: Chưa có automated test ánh xạ trực tiếp cho toàn bộ oracle của case này. | S6: 46249
A7: 6 | B7: F1-TC-006 | C7: F1-US1 | D7: Input & Places | E7: P0 | F7: FIXTURE | G7: Không tìm thấy địa điểm | H7: Người dùng nhập một tên địa điểm không tồn tại hoặc Place API trả zero result. | I7: Fixture Place Autocomplete trả danh sách rỗng. | J7: 1. Nhập địa điểm. 2. Chờ autocomplete. 3. Thử lập kế hoạch. | K7: UI thông báo không tìm thấy/không thể xác định tọa độ; không gọi planning workflow. | L7: Fixture: zero candidate; planner call count = 0. | M7: UI đã hiển thị ‘Không tìm thấy địa điểm’; cần bổ sung frontend component test. | Q7: NOT_AUTOMATED | R7: UI đã sửa; repository chưa có frontend component-test runner. | S7: 46249
A8: 7 | B8: F1-TC-007 | C8: F1-US1 | D8: Input & Places | E8: P0 | F8: FIXTURE | G8: Chỉ gõ text nhưng không chọn suggestion | H8: Người dùng gõ 'Vinh' nhưng không click kết quả Goong. | I8: Text field có chữ nhưng chưa có Place Detail/toạ độ. | J8: 1. Gõ địa điểm. 2. Click ra ngoài. 3. Bấm lập kế hoạch. | K8: Hệ thống không coi text chưa resolve là tọa độ xác nhận; yêu cầu chọn suggestion hoặc resolve rõ ràng. | L8: Fixture/UI state: thiếu resolved location → validation fail; planner call count = 0. | Q8: NOT_AUTOMATED | R8: Chưa có automated test ánh xạ trực tiếp cho toàn bộ oracle của case này. | S8: 46249
A9: 8 | B9: F1-TC-008 | C9: F1-US1 | D9: Input Validation | E9: P0 | F9: FIXTURE | G9: Thiếu điểm xuất phát | H9: Người dùng nhập destination và SOC nhưng bỏ trống origin. | I9: Destination hợp lệ; SOC 60%. | J9: 1. Để trống origin. 2. Bấm lập kế hoạch. | K9: Validation hiển thị lỗi tại origin; không gọi Goong Directions/VinFast/Open-Meteo/planner. | L9: Provider call count = 0; không tạo PlanProposal. | Q9: NOT_AUTOMATED | R9: Chưa có automated test ánh xạ trực tiếp cho toàn bộ oracle của case này. | S9: 46249
A10: 9 | B10: F1-TC-009 | C10: F1-US1 | D10: Input Validation | E10: P0 | F10: FIXTURE | G10: Thiếu điểm đến | H10: Người dùng nhập origin và SOC nhưng bỏ trống destination. | I10: Origin hợp lệ; SOC 60%. | J10: 1. Để trống destination. 2. Bấm lập kế hoạch. | K10: Validation hiển thị lỗi tại destination; không chạy planner. | L10: Provider call count = 0. | Q10: NOT_AUTOMATED | R10: Chưa có automated test ánh xạ trực tiếp cho toàn bộ oracle của case này. | S10: 46249
A11: 10 | B11: F1-TC-010 | C11: F1-US1 | D11: Input Validation | E11: P0 | F11: FIXTURE | G11: API từ chối request thiếu SOC | H11: Client/API gửi yêu cầu tạo trip nhưng không có initial_soc_percent. | I11: Origin/destination hợp lệ; bỏ field initial_soc_percent khỏi request. | J11: 1. POST /api/v1/trips không có initial_soc_percent. 2. Kiểm tra response và provider call count. | K11: API trả VALIDATION_ERROR; không tạo trip và không gọi planning workflow. | L11: HTTP 400; error.code=VALIDATION_ERROR; planner call count=0. | M11: Frontend luôn có SOC mặc định; đây là API/schema test. | N11: test_create_trip_rejects_missing_soc_at_api_boundary | O11: tests/test_api/test_trips.py | P11: API | Q11: PASS | R11: Chưa có automated test ánh xạ trực tiếp cho toàn bộ oracle của case này. | S11: 46249
A12: 11 | B12: F1-TC-011 | C12: F1-US1 | D12: Input Validation | E12: P0 | F12: FIXTURE | G12: SOC = 0% | H12: Người dùng nhập SOC không hợp lệ. | I12: Origin/destination hợp lệ. | J12: 1. Nhập SOC 0. 2. Bấm lập kế hoạch. | K12: Input bị từ chối tại validation; không được biến thành INFEASIBLE do planner. | L12: Validation error; planner/provider call count = 0. | M12: Ngưỡng input cụ thể nên theo implementation hiện hành. | N12: test_create_trip_rejects_invalid_soc | O12: tests/test_api/test_trips.py | P12: API | Q12: PASS | R12: Chưa có automated test ánh xạ trực tiếp cho toàn bộ oracle của case này. | S12: 46249
A13: 12 | B13: F1-TC-012 | C13: F1-US1 | D13: Input Validation | E13: P0 | F13: FIXTURE | G13: SOC > 100% | H13: Người dùng nhập 101% hoặc 150%. | I13: Origin/destination hợp lệ. | J13: 1. Nhập SOC 101. 2. Bấm lập kế hoạch. | K13: Input bị từ chối; hiển thị lỗi rõ ràng; không gọi planner. | L13: Validation error; provider call count = 0. | Q13: NOT_AUTOMATED | R13: Chưa có automated test ánh xạ trực tiếp cho toàn bộ oracle của case này. | S13: 46249
A14: 13 | B14: F1-TC-013 | C14: F1-US1 | D14: Input Validation | E14: P1 | F14: FIXTURE | G14: SOC là số thập phân hợp lệ | H14: Xe báo 60,5% và người dùng nhập giá trị thập phân. | I14: SOC schema hỗ trợ number. | J14: 1. Nhập 60.5. 2. Lập plan. | K14: Giá trị không bị làm tròn sai trước khi tính; backend nhận đúng số theo contract. | L14: Request/response fixture: initial SOC giữ đúng precision theo schema. | Q14: NOT_AUTOMATED | R14: Chưa có automated test ánh xạ trực tiếp cho toàn bộ oracle của case này. | S14: 46249
A15: 14 | B15: F1-TC-014 | C15: F1-US1 | D15: Input Validation | E15: P1 | F15: FIXTURE | G15: Điểm đi trùng điểm đến | H15: Người dùng chọn cùng một Place Detail cho origin và destination. | I15: Origin và destination có cùng tọa độ. | J15: 1. Chọn cùng địa điểm cho cả hai ô. 2. Lập plan. | K15: API từ chối có chủ đích; không gọi Goong Directions, station provider hoặc tạo plan. | L15: HTTP 422; error.code=VALIDATION_ERROR; details.reason=SAME_ORIGIN_DESTINATION. | M15: Behavior đã được chốt trong contract. | N15: test_create_trip_rejects_same_origin_and_destination | O15: tests/test_api/test_trips.py | P15: API | Q15: PASS | R15: Chưa có automated test ánh xạ trực tiếp cho toàn bộ oracle của case này. | S15: 46249
A16: 15 | B16: F1-TC-015 | C16: F1-US1 | D16: Input & Places | E16: P1 | F16: LIVE | G16: Người dùng từ chối quyền GPS | H16: Người dùng bấm lấy vị trí hiện tại nhưng browser từ chối quyền. | I16: Browser permission = denied. | J16: 1. Bấm lấy GPS. 2. Chọn Deny. 3. Tiếp tục nhập origin thủ công. | K16: UI báo không lấy được GPS nhưng vẫn cho nhập origin bằng Places; ứng dụng không treo. | L16: LIVE browser behavior; không ảnh hưởng Goong Places thủ công. | Q16: NOT_AUTOMATED | R16: Chưa có automated test ánh xạ trực tiếp cho toàn bộ oracle của case này. | S16: 46249
A17: 16 | B17: F1-TC-016 | C17: F1-US1 | D17: Provider Failure | E17: P0 | F17: FIXTURE | G17: Goong Places timeout | H17: Autocomplete/Place Detail chậm hoặc lỗi mạng. | I17: Mock Goong Places timeout/5xx. | J17: 1. Gõ địa điểm. 2. Provider timeout. 3. Thử lại hoặc đổi input. | K17: UI báo lỗi provider phù hợp; REST key không lộ; không tự sinh tọa độ. | L17: Mock timeout → normalized error; no fake coordinates. | Q17: NOT_AUTOMATED | R17: Chưa có automated test ánh xạ trực tiếp cho toàn bộ oracle của case này. | S17: 46249
A18: 17 | B18: F1-TC-017 | C18: F1-US1 | D18: Provider Failure | E18: P0 | F18: FIXTURE | G18: Place Detail trả payload thiếu tọa độ | H18: Autocomplete có suggestion nhưng detail response hỏng/thiếu lat-lng. | I18: Mock Place Detail malformed response. | J18: 1. Chọn suggestion. 2. Backend nhận payload thiếu dữ liệu bắt buộc. | K18: Fail closed; không đưa location thiếu tọa độ vào planner. | L18: Expected provider/validation failure; planner call count = 0. | Q18: NOT_AUTOMATED | R18: Chưa có automated test ánh xạ trực tiếp cho toàn bộ oracle của case này. | S18: 46249
A19: 18 | B19: F1-TC-018 | C19: F1-US2 | D19: Assumptions | E19: P0 | F19: LIVE | G19: Hiển thị reserve SOC 15% | H19: Người dùng cần biết ngưỡng an toàn đang áp dụng. | I19: Tạo một plan bất kỳ thành công. | J19: 1. Lập plan. 2. Mở khu vực giả định/thông số. | K19: UI hiển thị reserve 15% rõ ràng và mô tả đây là giả định/policy pilot, không phải khuyến nghị chung cho mọi xe. | L19: Expected exact reserve = 15%. | N19: test_get_current_assumptions_returns_versioned_policy_snapshot | O19: tests/test_api/test_trips.py | P19: API | Q19: NOT_AUTOMATED | R19: Có test fixture liên quan nhưng LIVE smoke này chưa được tự động hóa end-to-end. | S19: 46249
A20: 19 | B20: F1-TC-019 | C20: F1-US2 | D20: Vehicle Profile | E20: P0 | F20: LIVE | G20: Hiển thị đúng profile VinFast VF 6 Plus | H20: Người dùng cần biết hệ thống đang tính cho mẫu xe nào. | I20: Vehicle profile backend hiện hành. | J20: 1. Lập plan. 2. Kiểm tra thẻ thông số xe. | K20: Hiển thị VF 6 Plus, pin 59,6 kWh, CCS2, max DC 100 kW và version/profile source; không dùng số giả cũ. | L20: So với vehicle profile backend version hóa. | N20: test_vf6_profile_exposes_planning_and_official_vehicle_specs | O20: tests/test_api/test_trips.py | P20: API | Q20: NOT_AUTOMATED | R20: Có test fixture liên quan nhưng LIVE smoke này chưa được tự động hóa end-to-end. | S20: 46249
A21: 20 | B21: F1-TC-020 | C21: F1-US2 | D21: Assumptions | E21: P1 | F21: LIVE | G21: Môi trường thực tế được dùng trong phép tính | H21: Cùng tuyến nhưng điều kiện thời tiết hiện tại khác nhau. | I21: Open-Meteo hoạt động. | J21: 1. Lập plan. 2. Mở panel nguồn dữ liệu. 3. Kiểm tra nhiệt độ, mưa, gió, độ cao và effective consumption. | K21: Các giá trị môi trường có provenance/timestamp; effective consumption phản ánh input môi trường theo model. | L21: LIVE: không cố định con số; assert field đầy đủ, timestamp hợp lệ và effective consumption được backend trả. | Q21: NOT_AUTOMATED | R21: Chưa có automated test ánh xạ trực tiếp cho toàn bộ oracle của case này. | S21: 46249
A22: 21 | B22: F1-TC-021 | C22: F1-US2 | D22: Data Provenance | E22: P0 | F22: LIVE | G22: Nguồn route được hiển thị đúng | H22: Mentor cần biết route đang lấy thật từ đâu. | I22: Goong Directions thành công. | J22: 1. Lập plan. 2. Mở nguồn dữ liệu. | K22: Route hiển thị provider Goong, retrieved_at/source metadata; không gắn nhãn cached/simulated sai. | L22: Response route.provider/source/retrieved_at khớp UI. | Q22: NOT_AUTOMATED | R22: Chưa có automated test ánh xạ trực tiếp cho toàn bộ oracle của case này. | S22: 46249
A23: 22 | B23: F1-TC-022 | C23: F1-US2 | D23: Data Provenance | E23: P0 | F23: LIVE | G23: Nguồn trạm và freshness dùng thời điểm nguồn cập nhật | H23: Backend vừa tải VinFast Locator nhưng bản thân dữ liệu trạm có timestamp riêng. | I23: VinFast Locator detail có source_updated_at. | J23: 1. Lập plan. 2. Mở chi tiết station. 3. So retrieved_at với station_updated_at/freshness. | K23: Freshness được tính từ source_updated_at của trạm, không lấy thời điểm backend vừa fetch để giả làm dữ liệu mới. | L23: Compare freshness against station_updated_at/source timestamp. | Q23: NOT_AUTOMATED | R23: Chưa có automated test ánh xạ trực tiếp cho toàn bộ oracle của case này. | S23: 46249
A24: 23 | B24: F1-TC-023 | C24: F1-US2 | D24: Data Transparency | E24: P0 | F24: LIVE | G24: Không gọi ACTIVE/BUSY là cổng đang rảnh | H24: Trạm có charging_status ACTIVE hoặc BUSY trong VinFast metadata. | I24: Một station candidate có status ACTIVE/BUSY. | J24: 1. Mở popup/chi tiết trạm. 2. Đọc nhãn trạng thái. | K24: UI mô tả đây là metadata cấp trạm; không tuyên bố số cổng đang rảnh/đang sạc/hỏng theo thời gian thực. | L24: Text/UI audit; port_count chỉ là số connector tương thích trong payload detail. | Q24: NOT_AUTOMATED | R24: Chưa có automated test ánh xạ trực tiếp cho toàn bộ oracle của case này. | S24: 46249
A25: 24 | B25: F1-TC-024 | C25: F1-US2 | D25: Data Provenance | E25: P1 | F25: LIVE | G25: Origin, destination và SOC ban đầu được nhận diện là dữ liệu người dùng nhập | H25: Mentor kiểm tra tính minh bạch nguồn. | I25: Trip tạo từ form. | J25: 1. Lập plan. 2. Xem provenance/assumptions. | K25: Origin/destination chọn từ Goong có source_type=REAL_API; SOC ban đầu có source_type=MANUAL; không trình bày các input này như telemetry/OEM live. | L25: Coordinates selected via Goong Place Detail = REAL_API; initial SOC entered by user = MANUAL. | Q25: NOT_AUTOMATED | R25: Contract/API đã lưu REAL_API và MANUAL; LIVE UI provenance chưa có E2E test. | S25: 46249
A26: 25 | B26: F1-TC-025 | C26: F1-US2 | D26: UI/Contract Consistency | E26: P0 | F26: FIXTURE | G26: Frontend không tự tính lại SOC | H26: Backend trả soc_points và final_arrival_soc_percent cố định. | I26: Fixture plan có các điểm SOC biết trước. | J26: 1. Mock PlanProposal. 2. Render UI. 3. Đối chiếu chart, station popup, final SOC. | K26: Tất cả số SOC trên UI đúng với backend; không có công thức JS làm lệch số. | L26: Exact fixture values = UI values. | Q26: NOT_AUTOMATED | R26: Chưa có automated test ánh xạ trực tiếp cho toàn bộ oracle của case này. | S26: 46249
A27: 26 | B27: F1-TC-026 | C27: F1-US3 | D27: Happy Path | E27: P0 | F27: LIVE | G27: Chuyến ngắn không cần sạc | H27: Người dùng đi nội đô/quãng ngắn với SOC cao. | I27: Ví dụ nội đô Hà Nội; SOC 80–90%. | J27: 1. Chọn hai điểm cách nhau ngắn. 2. Nhập SOC cao. 3. Lập plan. | K27: Có route hợp lệ; charging_stops rỗng; SOC đích ≥15%; UI nói rõ đi thẳng được, không phải trạng thái lỗi. | L27: LIVE: assert feasibility + no stop + SOC reserve; không pin exact distance. | N27: test_short_safe_trip_does_not_require_station_provider | O27: tests/test_api/test_planning.py | P27: API integration | Q27: NOT_AUTOMATED | R27: Có test fixture liên quan nhưng LIVE smoke này chưa được tự động hóa end-to-end. | S27: 46249
A28: 27 | B28: F1-TC-027 | C28: F1-US3 | D28: Happy Path | E28: P0 | F28: LIVE | G28: Chuyến dài kiểm tra nhu cầu sạc theo dữ liệu live | H28: Chủ xe đi Hà Nội → Vinh với SOC khoảng 60%. | I28: Goong/VinFast/Open-Meteo hoạt động. | J28: 1. Lập plan. 2. Kiểm tra route, station, SOC arrival/departure và final SOC. | K28: Planner trả plan an toàn hoặc INFEASIBLE có lý do; nếu có trạm thì route từng leg dùng Goong waypoint, station CCS2 hợp lệ và mọi arrival SOC ≥15%. | L28: LIVE invariant; không khóa chính xác số trạm hoặc tên trạm. | M28: Muốn assert đúng một trạm phải dùng fixture version hóa riêng. | Q28: NOT_AUTOMATED | R28: Có fixture happy-path liên quan; LIVE smoke chưa chạy tự động. | S28: 46249
A29: 28 | B29: F1-TC-028 | C29: F1-US3 | D29: Happy Path | E29: P0 | F29: FIXTURE | G29: Chuyến rất dài cần nhiều điểm sạc | H29: Một tuyến dài hơn phạm vi một lần sạc, cần 2–5 stop. | I29: Fixture route/stations bảo đảm có chuỗi nhiều trạm. | J29: 1. Chạy planner với SOC ban đầu cố định. 2. Theo dõi chuỗi state. 3. Kiểm tra từng leg. | K29: Planner tìm được chuỗi stop đúng; không greedy chọn trạm khiến chặng sau bị kẹt; mọi leg ≥ reserve. | L29: Exact fixture station sequence và SOC từng leg. | Q29: NOT_AUTOMATED | R29: Chưa có automated test ánh xạ trực tiếp cho toàn bộ oracle của case này. | S29: 46249
A30: 29 | B30: F1-TC-029 | C30: F1-US3 | D30: Low SOC / Backtrack | E30: P0 | F30: LIVE | G30: SOC thấp kiểm tra khả năng backtrack gần origin | H30: Người dùng đi 10 Tạ Quang Bửu → VinUniversity với SOC 17%. | I30: Live providers hoạt động. | J30: 1. Nhập route và SOC 17%. 2. Lập plan. 3. Kiểm tra candidate gần/ở phía sau origin. | K30: Nếu có station backtracking được Goong xác minh và vẫn giữ SOC ≥15%, planner có thể chọn; nếu không có chuỗi an toàn thì trả INFEASIBLE minh bạch. | L30: LIVE invariant; không bắt buộc lần chạy live nào cũng phải có backtracking. | M30: Fixture F1-TC-030/F1-TC-063 dùng để assert exact hành vi backtracking. | Q30: NOT_AUTOMATED | R30: Có unit test backtracking liên quan; LIVE smoke chưa chạy tự động. | S30: 46249
A31: 30 | B31: F1-TC-030 | C31: F1-US3 | D31: Station Search | E31: P0 | F31: FIXTURE | G31: Candidate progress = 0 không bị loại | H31: Trạm rất gần điểm xuất phát nằm tại progress 0. | I31: Fixture station progress = 0, CCS2, reachable. | J31: 1. Chạy station shortlist. 2. Lập plan low-SOC. | K31: Candidate vẫn được đánh giá và có thể được chọn nếu thỏa toàn bộ hard constraints. | L31: Exact fixture candidate remains eligible. | N31: test_station_at_origin_progress_can_be_used_by_low_soc_trip | O31: tests/test_core/test_energy_planning.py | P31: Unit | Q31: PASS | R31: Chưa có automated test ánh xạ trực tiếp cho toàn bộ oracle của case này. | S31: 46249
A32: 31 | B32: F1-TC-031 | C32: F1-US3 | D32: Detour Boundary | E32: P0 | F32: FIXTURE | G32: Đường vòng đúng giới hạn 10 km và 15 phút | H32: Trạm cần rẽ khỏi tuyến nhưng đúng bằng giới hạn cho phép. | I32: Fixture waypoint: added_distance=10.00 km, added_time=15.00 min. | J32: 1. Lập plan. 2. Xác minh detour bằng Goong fixture. | K32: Candidate không bị loại chỉ vì nằm đúng boundary; vẫn tiếp tục feasibility. | L32: Boundary <=10 km AND <=15 min is accepted. | Q32: NOT_AUTOMATED | R32: Chưa có automated test ánh xạ trực tiếp cho toàn bộ oracle của case này. | S32: 46249
A33: 32 | B33: F1-TC-032 | C33: F1-US3 | D33: Detour Boundary | E33: P0 | F33: FIXTURE | G33: Đường vòng vượt 10 km | H33: Trạm phù hợp connector nhưng cách tuyến quá xa. | I33: Fixture added_distance=10.01 km, time <15 min. | J33: 1. Lập plan. | K33: Candidate bị loại dù SOC đủ; nếu không còn phương án an toàn, response chứa reason code DETOUR_DISTANCE_EXCEEDED. | L33: Exact rejected candidate; added_distance=10.01 km; reason_codes chứa DETOUR_DISTANCE_EXCEEDED. | N33: test_planner_reports_exact_detour_rejection[distance] | O33: tests/test_core/test_planning_detour.py | P33: Component | Q33: PASS | R33: Chưa có automated test ánh xạ trực tiếp cho toàn bộ oracle của case này. | S33: 46249
A34: 33 | B34: F1-TC-033 | C34: F1-US3 | D34: Detour Boundary | E34: P0 | F34: FIXTURE | G34: Đường vòng vượt 15 phút | H34: Trạm chỉ tăng 8 km nhưng mất 15.1 phút. | I34: Fixture added_distance<10 km, added_time=15.1 min. | J34: 1. Lập plan. | K34: Candidate bị loại theo time limit; nếu không còn phương án an toàn, response chứa reason code DETOUR_TIME_EXCEEDED. | L34: Exact rejected candidate; added_time=15.1 min; reason_codes chứa DETOUR_TIME_EXCEEDED. | N34: test_planner_reports_exact_detour_rejection[time] | O34: tests/test_core/test_planning_detour.py | P34: Component | Q34: PASS | R34: Chưa có automated test ánh xạ trực tiếp cho toàn bộ oracle của case này. | S34: 46249
A35: 34 | B35: F1-TC-034 | C35: F1-US3 | D35: Multiple Plans | E35: P0 | F35: FIXTURE | G35: Có ba phương án an toàn khác nhau | H35: Cùng trip có 3 chuỗi trạm an toàn với trade-off khác nhau. | I35: Fixture có ≥3 unique feasible paths. | J35: 1. Lập plan. 2. Quan sát selector phương án. | K35: API/UI trả tối đa 3 phương án; có cân bằng/nhanh/an toàn nếu thật sự khác nhau; tất cả đều đã qua feasibility. | L35: Exact feasible plan IDs ≤3; no infeasible plan in options. | Q35: NOT_AUTOMATED | R35: Chưa có automated test ánh xạ trực tiếp cho toàn bộ oracle của case này. | S35: 46249
A36: 35 | B36: F1-TC-035 | C36: F1-US3 | D36: Multiple Plans | E36: P1 | F36: FIXTURE | G36: Chỉ có một phương án an toàn | H36: Tuyến chỉ có một chuỗi station hợp lệ. | I36: Fixture chỉ một feasible path. | J36: 1. Lập plan. | K36: UI không nhân bản một plan thành ba option giả; chỉ hiển thị số phương án thực có. | L36: Unique plan count = 1. | Q36: NOT_AUTOMATED | R36: Chưa có automated test ánh xạ trực tiếp cho toàn bộ oracle của case này. | S36: 46249
A37: 36 | B37: F1-TC-036 | C37: F1-US3 | D37: Multiple Plans | E37: P1 | F37: FIXTURE | G37: Hai phương án có chuỗi trạm khác nhau | H37: Safety engine tìm được hai station chain khác nhau và Goong xác minh route waypoint tương ứng. | I37: Fixture có 2 station-chain identities khác nhau; mỗi chain có route geometry riêng. | J37: 1. Lập plan. 2. Chuyển option. | K37: Mỗi option giữ đúng station sequence, route geometry và SOC points của chính nó; map redraw đúng option. | L37: Exact station sequence + geometry hash + SOC points per plan. | M37: Nhiều geometry cho cùng một station chain nằm ngoài phạm vi F1 hiện tại. | Q37: NOT_AUTOMATED | R37: Oracle đã đổi sang station-chain identity; chưa có fixture hai chain. | S37: 46249
A38: 37 | B38: F1-TC-037 | C38: F1-US3 | D38: Connector | E38: P0 | F38: FIXTURE | G38: Loại trạm không có CCS2 | H38: Dọc tuyến có trạm CHAdeMO/Type2 nhưng xe VF 6 Plus yêu cầu CCS2. | I38: Fixture có mixed connectors. | J38: 1. Lập plan. | K38: Trạm không có CCS2 không xuất hiện trong charging plan. | L38: Rejected station ids/reason = connector mismatch/unknown. | N38: test_incompatible_connector_is_infeasible | O38: tests/test_core/test_feasibility.py | P38: Unit | Q38: PASS | R38: Chưa có automated test ánh xạ trực tiếp cho toàn bộ oracle của case này. | S38: 46249
A39: 38 | B39: F1-TC-038 | C39: F1-US3 | D39: Connector | E39: P0 | F39: FIXTURE | G39: Connector không rõ | H39: VinFast detail trả EVSE nhưng thiếu connector standard. | I39: Fixture malformed/unknown connector. | J39: 1. Lập plan. | K39: Trạm bị loại fail-closed; không suy đoán rằng connector tương thích. | L39: Rejected exact station. | Q39: NOT_AUTOMATED | R39: Chưa có automated test ánh xạ trực tiếp cho toàn bộ oracle của case này. | S39: 46249
A40: 39 | B40: F1-TC-039 | C40: F1-US3 | D40: Station Metadata | E40: P0 | F40: FIXTURE | G40: Công suất trạm không hợp lệ | H40: Trạm có CCS2 nhưng power null/0/âm. | I40: Fixture invalid max_power_kw. | J40: 1. Lập plan. | K40: Trạm không được dùng để tính thời gian sạc hoặc tạo plan. | L40: Rejected candidate; no fabricated power. | Q40: NOT_AUTOMATED | R40: Chưa có automated test ánh xạ trực tiếp cho toàn bộ oracle của case này. | S40: 46249
...

Sheet Live_Smoke
A1: STT | B1: Test ID | C1: Trường hợp | D1: Input / Tình huống | E1: Thực hiện | F1: Expected | G1: Lưu ý oracle
A2: 1 | B2: F1-TC-001 | C2: Lập kế hoạch với địa chỉ phổ biến | D2: Origin: Hà Nội; Destination: Vinh; SOC: 60%. | E2: 1. Gõ điểm đi và chọn đúng suggestion Goong. 2. Gõ điểm đến và chọn đúng suggestion. 3. Nhập SOC 60%. 4. Bấm lập kế hoạch. | F2: Trip được chấp nhận; tọa độ được resolve từ Place Detail; planner được gọi; không tự sửa địa điểm người dùng đã chọn. | G2: LIVE: kiểm tra invariants và Place ID/toạ độ được trả từ Goong tại thời điểm test; không cố định số route/trạm.
A3: 2 | B3: F1-TC-002 | C3: Dùng vị trí hiện tại làm điểm xuất phát | D3: Browser đã cấp quyền Location; destination hợp lệ; SOC 70%. | E3: 1. Bấm nút lấy vị trí hiện tại. 2. Chờ GPS resolve. 3. Chọn destination. 4. Lập plan. | F3: Origin được gắn từ GPS/browser; UI hiển thị đúng vị trí; không lấy một địa điểm ngẫu nhiên từ autocomplete. | G3: LIVE: so vị trí với GPS thiết bị trong sai số chấp nhận của browser; không hard-code tọa độ.
A4: 3 | B4: F1-TC-003 | C4: Đổi chiều điểm đi và điểm đến | D4: Hai điểm đã được chọn từ suggestion; SOC 80%. | E4: 1. Chọn Hà Nội làm origin, Vinh làm destination. 2. Bấm đổi chiều. 3. Lập plan. | F4: Origin/destination đổi đúng cả label và tọa độ; route được tính theo chiều mới. | G4: LIVE: kiểm tra request gửi backend chứa tọa độ sau khi đảo chiều.
A5: 4 | B5: F1-TC-004 | C5: Tìm địa điểm bằng chuỗi không dấu / sai chính tả nhẹ | D5: Goong Places hoạt động. | E5: 1. Nhập chuỗi gần đúng. 2. Quan sát suggestion. 3. Chọn một kết quả cụ thể. 4. Lập plan. | F5: Hệ thống chỉ dùng địa điểm mà người dùng đã chọn; không tự đoán từ text chưa xác nhận. | G5: LIVE: suggestion phụ thuộc Goong; oracle là selected Place Detail phải khớp request planner.
A6: 5 | B6: F1-TC-015 | C6: Người dùng từ chối quyền GPS | D6: Browser permission = denied. | E6: 1. Bấm lấy GPS. 2. Chọn Deny. 3. Tiếp tục nhập origin thủ công. | F6: UI báo không lấy được GPS nhưng vẫn cho nhập origin bằng Places; ứng dụng không treo. | G6: LIVE browser behavior; không ảnh hưởng Goong Places thủ công.
A7: 6 | B7: F1-TC-018 | C7: Hiển thị reserve SOC 15% | D7: Tạo một plan bất kỳ thành công. | E7: 1. Lập plan. 2. Mở khu vực giả định/thông số. | F7: UI hiển thị reserve 15% rõ ràng và mô tả đây là giả định/policy pilot, không phải khuyến nghị chung cho mọi xe. | G7: Expected exact reserve = 15%.
A8: 7 | B8: F1-TC-019 | C8: Hiển thị đúng profile VinFast VF 6 Plus | D8: Vehicle profile backend hiện hành. | E8: 1. Lập plan. 2. Kiểm tra thẻ thông số xe. | F8: Hiển thị VF 6 Plus, pin 59,6 kWh, CCS2, max DC 100 kW và version/profile source; không dùng số giả cũ. | G8: So với vehicle profile backend version hóa.
A9: 8 | B9: F1-TC-020 | C9: Môi trường thực tế được dùng trong phép tính | D9: Open-Meteo hoạt động. | E9: 1. Lập plan. 2. Mở panel nguồn dữ liệu. 3. Kiểm tra nhiệt độ, mưa, gió, độ cao và effective consumption. | F9: Các giá trị môi trường có provenance/timestamp; effective consumption phản ánh input môi trường theo model. | G9: LIVE: không cố định con số; assert field đầy đủ, timestamp hợp lệ và effective consumption được backend trả.
A10: 9 | B10: F1-TC-021 | C10: Nguồn route được hiển thị đúng | D10: Goong Directions thành công. | E10: 1. Lập plan. 2. Mở nguồn dữ liệu. | F10: Route hiển thị provider Goong, retrieved_at/source metadata; không gắn nhãn cached/simulated sai. | G10: Response route.provider/source/retrieved_at khớp UI.
A11: 10 | B11: F1-TC-022 | C11: Nguồn trạm và freshness dùng thời điểm nguồn cập nhật | D11: VinFast Locator detail có source_updated_at. | E11: 1. Lập plan. 2. Mở chi tiết station. 3. So retrieved_at với station_updated_at/freshness. | F11: Freshness được tính từ source_updated_at của trạm, không lấy thời điểm backend vừa fetch để giả làm dữ liệu mới. | G11: Compare freshness against station_updated_at/source timestamp.
A12: 11 | B12: F1-TC-023 | C12: Không gọi ACTIVE/BUSY là cổng đang rảnh | D12: Một station candidate có status ACTIVE/BUSY. | E12: 1. Mở popup/chi tiết trạm. 2. Đọc nhãn trạng thái. | F12: UI mô tả đây là metadata cấp trạm; không tuyên bố số cổng đang rảnh/đang sạc/hỏng theo thời gian thực. | G12: Text/UI audit; port_count chỉ là số connector tương thích trong payload detail.
A13: 12 | B13: F1-TC-024 | C13: Origin, destination và SOC ban đầu được nhận diện là dữ liệu người dùng nhập | D13: Trip tạo từ form. | E13: 1. Lập plan. 2. Xem provenance/assumptions. | F13: Origin/destination chọn từ Goong có source_type=REAL_API; SOC ban đầu có source_type=MANUAL; không trình bày các input này như telemetry/OEM live. | G13: Coordinates selected via Goong Place Detail = REAL_API; initial SOC entered by user = MANUAL.
... A21: 20 | B21: F1-TC-084 | C21: Route/trạm không dùng OpenStreetMap/Leaflet cũ | D21: Production build. | E21: 1. Inspect bundle/network. 2. Lập plan. | F21: Không có tile.openstreetmap, Leaflet/react-leaflet; map và route chạy trên Goong stack hiện hành. | G21: Bundle/network audit.

Sheet Coverage
A1: Hạng mục | B1: Số case | C1: P0 | D1: P1 | E1: LIVE | F1: FIXTURE | H1: Tổng quan | I1: Giá trị
A2: F1-US1 | B2: =COUNTIF(F1_Test_Cases!$C$2:$C$85,A2) | C2: =COUNTIFS(F1_Test_Cases!$C$2:$C$85,A2,F1_Test_Cases!$E$2:$E$85,"P0") | D2: =COUNTIFS(F1_Test_Cases!$C$2:$C$85,A2,F1_Test_Cases!$E$2:$E$85,"P1") | E2: =COUNTIFS(F1_Test_Cases!$C$2:$C$85,A2,F1_Test_Cases!$F$2:$F$85,"LIVE") | F2: =COUNTIFS(F1_Test_Cases!$C$2:$C$85,A2,F1_Test_Cases!$F$2:$F$85,"FIXTURE") | H2: Tổng số test case | I2: 84
A3: F1-US2 | B3: =COUNTIF(F1_Test_Cases!$C$2:$C$85,A3) | C3: =COUNTIFS(F1_Test_Cases!$C$2:$C$85,A3,F1_Test_Cases!$E$2:$E$85,"P0") | D3: =COUNTIFS(F1_Test_Cases!$C$2:$C$85,A3,F1_Test_Cases!$E$2:$E$85,"P1") | E3: =COUNTIFS(F1_Test_Cases!$C$2:$C$85,A3,F1_Test_Cases!$F$2:$F$85,"LIVE") | F3: =COUNTIFS(F1_Test_Cases!$C$2:$C$85,A3,F1_Test_Cases!$F$2:$F$85,"FIXTURE") | H3: LIVE smoke case | I3: 20
A4: F1-US3 | B4: =COUNTIF(F1_Test_Cases!$C$2:$C$85,A4) | C4: =COUNTIFS(F1_Test_Cases!$C$2:$C$85,A4,F1_Test_Cases!$E$2:$E$85,"P0") | D4: =COUNTIFS(F1_Test_Cases!$C$2:$C$85,A4,F1_Test_Cases!$E$2:$E$85,"P1") | E4: =COUNTIFS(F1_Test_Cases!$C$2:$C$85,A4,F1_Test_Cases!$F$2:$F$85,"LIVE") | F4: =COUNTIFS(F1_Test_Cases!$C$2:$C$85,A4,F1_Test_Cases!$F$2:$F$85,"FIXTURE") | H4: P0 | I4: 58
A5: F1-US4 | B5: =COUNTIF(F1_Test_Cases!$C$2:$C$85,A5) | C5: =COUNTIFS(F1_Test_Cases!$C$2:$C$85,A5,F1_Test_Cases!$E$2:$E$85,"P0") | D5: =COUNTIFS(F1_Test_Cases!$C$2:$C$85,A5,F1_Test_Cases!$E$2:$E$85,"P1") | E5: =COUNTIFS(F1_Test_Cases!$C$2:$C$85,A5,F1_Test_Cases!$F$2:$F$85,"LIVE") | F5: =COUNTIFS(F1_Test_Cases!$C$2:$C$85,A5,F1_Test_Cases!$F$2:$F$85,"FIXTURE") | H5: P1 | I5: 26
A6: F1-US3/F1-US4 | B6: =COUNTIF(F1_Test_Cases!$C$2:$C$85,A6) | C6: =COUNTIFS(F1_Test_Cases!$C$2:$C$85,A6,F1_Test_Cases!$E$2:$E$85,"P0") | D6: =COUNTIFS(F1_Test_Cases!$C$2:$C$85,A6,F1_Test_Cases!$E$2:$E$85,"P1") | E6: =COUNTIFS(F1_Test_Cases!$C$2:$C$85,A6,F1_Test_Cases!$F$2:$F$85,"LIVE") | F6: =COUNTIFS(F1_Test_Cases!$C$2:$C$85,A6,F1_Test_Cases!$F$2:$F$85,"FIXTURE") | H6: Phạm vi | I6: F1-US1 → F1-US4
A7: F1-US1/F1-US3 | B7: =COUNTIF(F1_Test_Cases!$C$2:$C$85,A7) | C7: =COUNTIFS(F1_Test_Cases!$C$2:$C$85,A7,F1_Test_Cases!$E$2:$E$85,"P0") | D7: =COUNTIFS(F1_Test_Cases!$C$2:$C$85,A7,F1_Test_Cases!$E$2:$E$85,"P1") | E7: =COUNTIFS(F1_Test_Cases!$C$2:$C$85,A7,F1_Test_Cases!$F$2:$F$85,"LIVE") | F7: =COUNTIFS(F1_Test_Cases!$C$2:$C$85,A7,F1_Test_Cases!$F$2:$F$85,"FIXTURE")
A10: Nhóm kiểm thử | B10: Số case | C10: P0 | D10: P1
A11: AI Boundary | B11: =COUNTIF(F1_Test_Cases!$D$2:$D$85,A11) | C11: =COUNTIFS(F1_Test_Cases!$D$2:$D$85,A11,F1_Test_Cases!$E$2:$E$85,"P0") | D11: =COUNTIFS(F1_Test_Cases!$D$2:$D$85,A11,F1_Test_Cases!$E$2:$E$85,"P1")
A12: Assumptions | B12: =COUNTIF(F1_Test_Cases!$D$2:$D$85,A12) | C12: =COUNTIFS(F1_Test_Cases!$D$2:$D$85,A12,F1_Test_Cases!$E$2:$E$85,"P0") | D12: =COUNTIFS(F1_Test_Cases!$D$2:$D$85,A12,F1_Test_Cases!$E$2:$E$85,"P1")
A13: Charge Target | B13: =COUNTIF(F1_Test_Cases!$D$2:$D$85,A13) | C13: =COUNTIFS(F1_Test_Cases!$D$2:$D$85,A13,F1_Test_Cases!$E$2:$E$85,"P0") | D13: =COUNTIFS(F1_Test_Cases!$D$2:$D$85,A13,F1_Test_Cases!$E$2:$E$85,"P1")
A14: Charging Time | B14: =COUNTIF(F1_Test_Cases!$D$2:$D$85,A14) | C14: =COUNTIFS(F1_Test_Cases!$D$2:$D$85,A14,F1_Test_Cases!$E$2:$E$85,"P0") | D14: =COUNTIFS(F1_Test_Cases!$D$2:$D$85,A14,F1_Test_Cases!$E$2:$E$85,"P1")
A15: Connector | B15: =COUNTIF(F1_Test_Cases!$D$2:$D$85,A15) | C15: =COUNTIFS(F1_Test_Cases!$D$2:$D$85,A15,F1_Test_Cases!$E$2:$E$85,"P0") | D15: =COUNTIFS(F1_Test_Cases!$D$2:$D$85,A15,F1_Test_Cases!$E$2:$E$85,"P1")
A16: Contract | B16: =COUNTIF(F1_Test_Cases!$D$2:$D$85,A16) | C16: =COUNTIFS(F1_Test_Cases!$D$2:$D$85,A16,F1_Test_Cases!$E$2:$E$85,"P0") | D16: =COUNTIFS(F1_Test_Cases!$D$2:$D$85,A16,F1_Test_Cases!$E$2:$E$85,"P1")
A17: Data Provenance | B17: =COUNTIF(F1_Test_Cases!$D$2:$D$85,A17) | C17: =COUNTIFS(F1_Test_Cases!$D$2:$D$85,A17,F1_Test_Cases!$E$2:$E$85,"P0") | D17: =COUNTIFS(F1_Test_Cases!$D$2:$D$85,A17,F1_Test_Cases!$E$2:$E$85,"P1")
A18: Data Transparency | B18: =COUNTIF(F1_Test_Cases!$D$2:$D$85,A18) | C18: =COUNTIFS(F1_Test_Cases!$D$2:$D$85,A18,F1_Test_Cases!$E$2:$E$85,"P0") | D18: =COUNTIFS(F1_Test_Cases!$D$2:$D$85,A18,F1_Test_Cases!$E$2:$E$85,"P1")
A19: Dense Urban | B19: =COUNTIF(F1_Test_Cases!$D$2:$D$85,A19) | C19: =COUNTIFS(F1_Test_Cases!$D$2:$D$85,A19,F1_Test_Cases!$E$2:$E$85,"P0") | D19: =COUNTIFS(F1_Test_Cases!$D$2:$D$85,A19,F1_Test_Cases!$E$2:$E$85,"P1")
A20: Detour Boundary | B20: =COUNTIF(F1_Test_Cases!$D$2:$D$85,A20) | C20: =COUNTIFS(F1_Test_Cases!$D$2:$D$85,A20,F1_Test_Cases!$E$2:$E$85,"P0") | D20: =COUNTIFS(F1_Test_Cases!$D$2:$D$85,A20,F1_Test_Cases!$E$2:$E$85,"P1")
A21: Environment | B21: =COUNTIF(F1_Test_Cases!$D$2:$D$85,A21) | C21: =COUNTIFS(F1_Test_Cases!$D$2:$D$85,A21,F1_Test_Cases!$E$2:$E$85,"P0") | D21: =COUNTIFS(F1_Test_Cases!$D$2:$D$85,A21,F1_Test_Cases!$E$2:$E$85,"P1")
A22: Fail Closed | B22: =COUNTIF(F1_Test_Cases!$D$2:$D$85,A22) | C22: =COUNTIFS(F1_Test_Cases!$D$2:$D$85,A22,F1_Test_Cases!$E$2:$E$85,"P0") | D22: =COUNTIFS(F1_Test_Cases!$D$2:$D$85,A22,F1_Test_Cases!$E$2:$E$85,"P1")
... A49: Waypoint Routing | B49: =COUNTIF(F1_Test_Cases!$D$2:$D$85,A49) | C49: =COUNTIFS(F1_Test_Cases!$D$2:$D$85,A49,F1_Test_Cases!$E$2:$E$85,"P0") | D49: =COUNTIFS(F1_Test_Cases!$D$2:$D$85,A49,F1_Test_Cases!$E$2:$E$85,"P1")

Sheet GroundTruth_Rules
A1: Nguyên tắc | B1: Cách áp dụng cho F1
A2: 1. LIVE smoke ≠ benchmark exact | B2: Goong route, VinFast generation/station metadata và Open-Meteo có thể thay đổi. LIVE chỉ assert invariants: đúng connector, reserve SOC ≥15%, provenance đúng, provider errors đúng, không bịa route/trạm.
A3: 2. FIXTURE dùng cho ground truth | B3: APP_ENV=test dùng route/station/environment fixture cố định. Các case boundary, connector, detour, charge target, provider failure và AI boundary phải assert exact expected output.
A4: 3. Không lấy dữ liệu live làm đáp án chuẩn | B4: Không chốt cứng 'phải chọn Trạm X' cho một live test dài hạn. Chỉ chốt station ID trong snapshot/fixture version hóa.
A5: 4. Safety oracle | B5: Mọi leg của PlanProposal hợp lệ phải có arrival SOC ≥15%; station phải được xác minh CCS2 và power hợp lệ; route từng leg phải là route provider/fixture thật; không có dữ liệu safety-critical thì fail closed.
A6: 5. Provider failure ≠ INFEASIBLE | B6: Goong lỗi → ROUTING_UNAVAILABLE; Open-Meteo lỗi → ENVIRONMENT_DATA_UNAVAILABLE. VinFast lỗi chỉ trả STATION_DATA_UNAVAILABLE khi hành trình cần sạc; chuyến đi thẳng đã chứng minh an toàn không phụ thuộc Locator.
A7: 6. AI không phải ground truth | B7: OpenAI chỉ xếp hạng các plan đã feasible và giải thích. AI tắt/lỗi/đưa plan_id ngoài tập cho phép không được thay đổi deterministic feasibility.
A8: 7. Data transparency | B8: ACTIVE/BUSY là metadata cấp trạm, không phải live availability từng cổng. port_count không phải số cổng đang rảnh.
A9: 8. Vehicle/policy hiện hành | B9: VF 6 Plus profile: usable/danh định theo profile backend hiện hành; tài liệu F1-US3 ghi pin 59,6 kWh, CCS2, max DC 100 kW. Reserve benchmark/pilot = 15%.
A10: 9. Backtracking/search scope | B10: Backtrack/detour chỉ chấp nhận khi route waypoint xác minh phần tăng thêm không vượt 10 km và 15 phút. Search tối đa 5 charging stops, UI tối đa 3 phương án an toàn.
A11: 10. Regression gate | B11: P0 phải pass trước demo/release. LIVE smoke nên chạy trên production sau deploy; FIXTURE P0 chạy trong CI/benchmark để tránh phụ thuộc provider live.
A12: 11. Station degradation/cache | B12: Có thể dùng cache locator đã tải khi refresh metadata lỗi và phải giữ source_updated_at/freshness. Detail lỗi một phần được bỏ qua; nếu không còn dữ liệu đủ để chứng minh chuỗi sạc an toàn thì fail closed.
A13: 12. Pilot model oracle | B13: Hệ số công suất ×0,85, mục tiêu sạc 80% và các hệ số thời tiết/tải là oracle của mô hình pilot, không phải ground truth vật lý hoặc cam kết OEM.

Sheet Automation
A1: Automation status | B1: Số case | C1: Ý nghĩa
A2: PASS | B2: =COUNTIF(F1_Test_Cases!$Q$2:$Q$85,"PASS") | C2: Có automated test ánh xạ trực tiếp và đã pass trong lần verify.
A3: FAIL | B3: =COUNTIF(F1_Test_Cases!$Q$2:$Q$85,"FAIL") | C3: Automated test ánh xạ trực tiếp nhưng đang fail.
A4: NOT_AUTOMATED | B4: =COUNTIF(F1_Test_Cases!$Q$2:$Q$85,"NOT_AUTOMATED") | C4: Chưa có automated test bao phủ đầy đủ oracle của case.
A6: Quy ước normalize | C6: Không so UUID, plan_id, created_at, retrieved_at hoặc timestamp động trong fixture reproducibility.
A7: LIVE | C7: Chỉ assert invariant; không khóa tên trạm, số trạm hoặc route geometry theo thời gian.
A8: FIXTURE | C8: Dùng oracle exact và provider offline/version hóa.
